Workbook

Sheet 1. Raw Data - Bloomberg
B2: Starbucks Corp (SBUX US) - BBG Adjusted
B3: In Millions of USD except Per Share | C3: In Millions of USD except Per Share | D3: FY 2015 | E3: FY 2016 | F3: FY 2017 | G3: FY 2018 | H3: FY 2019 | I3: FY 2020 | J3: FY 2021 | K3: FY 2022 | L3: FY 2023 | M3: FY 2024
B4: 12 Months Ending | C4: 12 Months Ending | D4: 09/27/2015 | E4: 10/02/2016 | F4: 10/01/2017 | G4: 09/30/2018 | H4: 09/29/2019 | I4: 09/27/2020 | J4: 10/03/2021 | K4: 10/02/2022 | L4: 10/01/2023 | M4: 09/29/2024
B5: Revenue | C5: Revenue | D5: 19162.7 | E5: 21315.9 | F5: 22386.8 | G5: 24719.5 | H5: 26508.6 | I5: 23518 | J5: 29060.6 | K5: 32250.3 | L5: 35975.6 | M5: 36176.2
B6: + Sales & Services Revenue | C6: + Sales & Services Revenue | D6: 17300.8 | E6: 19161.7 | F6: 20005.7 | G6: 22067.3 | H6: 23633.6 | I6: 21190.9 | J6: 26377 | K6: 28594.8 | L6: 31462.9 | M6: 31671.1 | AD6: Income Statement
B7: + Other Revenue | C7: + Other Revenue | D7: 1861.9 | E7: 2154.2 | F7: 2381.1 | G7: 2652.2 | H7: 2875 | I7: 2327.1 | J7: 2683.6 | K7: 3655.5 | L7: 4512.7 | M7: 4505.1
B8: - Cost of Revenue | C8: - Cost of Revenue | D8: 13198.6 | E8: 14573.3 | F8: 15552.2 | G8: 17402.9 | H8: 19020.5 | I8: 18458.9 | J8: 20652 | K8: 23879.2 | L8: 26129.4 | M8: 26467.1 | AD8: Balance Sheet
B9: + Cost of Goods & Services | C9: + Cost of Goods & Services | D9: 13198.6 | E9: 14573.3 | F9: 15552.2 | G9: 17402.9 | H9: 19020.5 | I9: 18458.9 | J9: 20652 | K9: 23879.2 | L9: 26129.4 | M9: 26467.1 | AD9: Cashflow Statement
B10: Gross Profit | C10: Gross Profit | D10: 5964.1 | E10: 6742.6 | F10: 6834.6 | G10: 7316.6 | H10: 7488.1 | I10: 5059.1 | J10: 8408.6 | K10: 8371.1 | L10: 9846.2 | M10: 9709.1 | AD10: Revenue Break-up
B11: + Other Operating Income | C11: + Other Operating Income | D11: 0 | E11: 318.2 | F11: 391.4 | G11: 301.2 | H11: 298 | I11: 322.5 | J11: 385.3 | K11: 234.1 | L11: 298.4 | M11: 301.2 | AD11: Additional Information
B12: - Operating Expenses | C12: - Operating Expenses | D12: 2308.5 | E12: 2888.9 | F12: 2874.8 | G12: 3122.8 | H12: 3215.6 | I12: 3248.4 | J12: 3576 | K12: 3750.2 | L12: 4343.2 | M12: 4480
B13: + Selling, General & Admin | C13: + Selling, General & Admin | D13: 1424.6 | E13: 1657.5 | F13: 1691 | G13: 1968.5 | H13: 2029 | I13: 1922.2 | J13: 2215.5 | K13: 2448.7 | L13: 2949.1 | M13: 2523.3
B14: + Selling & Marketing | C14: + Selling & Marketing | D14: 227.9 | E14: 248.6 | F14: 282.6 | G14: 260.3 | H14: 245.7 | I14: 258.8 | J14: 305.1 | K14: 416.7 | L14: 507.8 | M14: 0
B15: + General & Administrative | C15: + General & Administrative | D15: 1196.7 | E15: 1408.9 | F15: 1408.4 | G15: 1708.2 | H15: 1783.3 | I15: 1663.4 | J15: 1910.4 | K15: 2032 | L15: 2441.3 | M15: 2523.3
B16: + Research & Development | C16: + Research & Development | D16: 0 | E16: 0 | F16: 0 | G16: 0 | H16: 0 | I16: 0 | J16: 0 | K16: 0 | L16: 0 | M16: 0
B17: + Depreciation & Amortization | C17: + Depreciation & Amortization | D17: 893.9 | E17: 980.8 | F17: 1011.4 | G17: 1247 | H17: 1377.3 | I17: 1431.3 | J17: 1441.7 | K17: 1447.9 | L17: 1362.6 | M17: 1512.6
B18: + Other Operating Expense | C18: + Other Operating Expense | D18: -10 | E18: 250.6 | F18: 172.4 | G18: -92.7 | H18: -190.7 | I18: -105.1 | J18: -81.2 | K18: -146.4 | L18: 31.5 | M18: 444.1
B19: Operating Income (Loss) | C19: Operating Income (Loss) | D19: 3655.6 | E19: 4171.9 | F19: 4351.2 | G19: 4495 | H19: 4570.5 | I19: 2133.2 | J19: 5217.9 | K19: 4855 | L19: 5801.4 | M19: 5530.3
B20: - Non-Operating (Income) Loss | C20: - Non-Operating (Income) Loss | D20: 27.5 | E20: -21.3 | F20: -89.3 | G20: -21.1 | H20: 234.5 | I20: 397.3 | J20: 379.7 | K20: 385.9 | L20: 468.9 | M20: 439.2
B21: + Interest Expense, Net | C21: + Interest Expense, Net | D21: 0 | E21: 0 | F21: 0 | G21: 0 | H21: 0 | I21: 0 | J21: 0 | K21: 482.9 | L21: 550.1 | M21: 562
B22: + Interest Expense | C22: + Interest Expense | D22: 70.5 | E22: 81.3 | F22: 92.5 | G22: 170.3 | H22: 331 | I22: 437 | J22: 469.8 | K22: 482.9 | L22: 550.1 | M22: 562
B23: - Interest Income | C23: - Interest Income | D23: 0 | E23: 0 | F23: 0 | G23: 0 | H23: 0 | I23: 0 | J23: 0 | K23: 0 | L23: 0 | M23: 0
... B64: Diluted EPS from Cont Ops, Adjusted | C64: Diluted EPS from Cont Ops, Adjusted | D64: 1.7019 | E64: 1.8976 | F64: 2.0456 | G64: 2.6924 | H64: 2.8384 | I64: 1.172 | J64: 3.1943 | K64: 2.9918 | L64: 3.5324 | M64: 3.3944
B66: Reference Items | C66: Reference Items
B67: Accounting Standard | C67: Accounting Standard | D67: US GAAP | E67: US GAAP | F67: US GAAP | G67: US GAAP | H67: US GAAP | I67: US GAAP | J67: US GAAP | K67: US GAAP | L67: US GAAP | M67: US GAAP
B68: EBITDA | C68: EBITDA | D68: 4589.4 | E68: 5202 | F68: 5418.3 | G68: 5800.9 | H68: 6019.8 | I68: 5210 | J68: 8321.2 | K68: 7939.2 | L68: 8852.7 | M68: 8846.2
B69: EBITDA Margin (T12M) | C69: EBITDA Margin (T12M) | D69: 23.9497 | E69: 24.4043 | F69: 24.2031 | G69: 23.4669 | H69: 22.7089 | I69: 22.1532 | J69: 28.634 | K69: 24.6174 | L69: 24.6075 | M69: 24.4531
B70: EBITA | C70: EBITA | D70: 3745.5 | E70: 4278.5 | F70: 4464.4 | G70: 4740.4 | H70: 4875.3 | I70: 4002.4 | J70: 7102.9 | K70: 6684 | L70: 7511.6 | M70: 7354
B71: EBIT | C71: EBIT | D71: 3655.6 | E71: 4171.9 | F71: 4351.2 | G71: 4495 | H71: 4570.5 | I71: 2133.2 | J71: 5217.9 | K71: 4855 | L71: 5801.4 | M71: 5530.3
B72: Gross Margin | C72: Gross Margin | D72: 31.1235 | E72: 31.6318 | F72: 30.5296 | G72: 29.5985 | H72: 28.2478 | I72: 21.5116 | J72: 28.9347 | K72: 25.9567 | L72: 27.3691 | M72: 26.8384
B73: Operating Margin | C73: Operating Margin | D73: 19.0766 | E73: 19.5718 | F73: 19.4365 | G73: 18.184 | H73: 17.2416 | I73: 9.0705 | J73: 17.9552 | K73: 15.0541 | L73: 16.1259 | M73: 15.2871
B74: Profit Margin | C74: Profit Margin | D74: 13.457 | E74: 13.2023 | F74: 13.3792 | G74: 15.1887 | H74: 13.1978 | I74: 5.8669 | J74: 13.0401 | K74: 10.7565 | L74: 11.3123 | M74: 10.6614
B75: Sales per Employee | C75: Sales per Employee | D75: 80515.546 | E75: 83920.866 | F75: 80818.773 | G75: 84946.735 | H75: 76614.451 | I75: 67386.819 | J75: 75876.24 | K75: 80224.627 | L75: 94424.147 | M75: 100211.08
B76: Dividends per Share | C76: Dividends per Share | D76: 0.68 | E76: 0.85 | F76: 1.05 | G76: 1.32 | H76: 1.49 | I76: 1.68 | J76: 1.84 | K76: 1.96 | L76: 2.12 | M76: 2.32
B77: Total Cash Common Dividends | C77: Total Cash Common Dividends | D77: 1016.2 | E77: 1246.2 | F77: 1521.975 | G77: 1825.164 | H77: 1819.588 | I77: 1970.304 | J77: 2166.784 | K77: 2260.468 | L77: 2431.216 | M77: 2630.416
B78: Capitalized Interest Expense | C78: Capitalized Interest Expense | D78: 3.6 | E78: 0 | F78: 0 | G78: 0 | H78: 0 | I78: 0 | J78: 0 | K78: 0 | L78: 0 | M78: 0
B79: Depreciation Expense | C79: Depreciation Expense | D79: 843.9 | E79: 923.5 | F79: 953.9 | G79: 1060.5 | H79: 1144.5 | I79: 1207.6 | J79: 1218.3 | K79: 1255.2 | L79: 1341.1 | M79: 1492.2
B80: Rental Expense | C80: Rental Expense | D80: 1137.8 | E80: 1223.2 | F80: 1329.2 | G80: 1625.2 | H80: 1666 | I80: 2441.1 | J80: 2559.7 | K80: 2522 | L80: 2679.3 | M80: 2881
B81: Source: Bloomberg
B84: Starbucks Corp (SBUX US) - Standardized
...

Sheet 2. Integrated Finance
B2: Integrated Finance - Starbucks Corp
B5: INCOME STATEMENT
A6: # | B6: PARTICULARS | C6: ACTUALS | M6: NEAR TERM FORECAST | R6: FAR TERM FORECAST | AB6: CV
C7: =2015 -> 2015 | D7: =C7+1 -> 2016 | E7: =D7+1 -> 2017 | F7: =E7+1 -> 2018 | G7: =F7+1 -> 2019 | H7: =G7+1 -> 2020 | I7: =H7+1 -> 2021 | J7: =I7+1 -> 2022 | K7: =J7+1 -> 2023 | ... BV7: =BU7+1 -> 2086
C8: ="FY "&C7 -> FY 2015 | D8: ="FY "&D7 -> FY 2016 | E8: ="FY "&E7 -> FY 2017 | F8: ="FY "&F7 -> FY 2018 | G8: ="FY "&G7 -> FY 2019 | H8: ="FY "&H7 -> FY 2020 | I8: ="FY "&I7 -> FY 2021 | J8: ="FY "&J7 -> FY 2022 | ... AA8: ="FY "&AA7 -> FY 2039 | AB8: Perpetuity
B9: Revenue | C9: ='1. Raw Data - Bloomberg'!D5 -> 19162.7 | D9: ='1. Raw Data - Bloomberg'!E5 -> 21315.9 | E9: ='1. Raw Data - Bloomberg'!F5 -> 22386.8 | F9: ='1. Raw Data - Bloomberg'!G5 -> 24719.5 | G9: ='1. Raw Data - Bloomberg'!H5 -> 26508.6 | H9: ='1. Raw Data - Bloomberg'!I5 -> 23518 | I9: ='1. Raw Data - Bloomberg'!J5 -> 29060.6 | J9: ='1. Raw Data - Bloomberg'!K5 -> 32250.3 | ... L9: ='1. Raw Data - Bloomberg'!M5 -> 36176.2 | M9: =M10+M12+M11 -> 39113.905 | N9: =N10+N12+N11 -> 42309.723 | O9: =O10+O12+O11 -> 45786.613 | P9: =P10+P12+P11 -> 49569.62 | Q9: =Q10+Q12+Q11 -> 53686.068 | R9: =R10+R12+R11 -> 58165.776 | S9: =S10+S12+S11 -> 63041.287 | T9: =T10+T12+T11 -> 68348.127 | ... AB9: =AB10+AB12+AB11 -> 131826.12
B10: Company Operated Retail | C10: ='1. Raw Data - Bloomberg'!D260 -> 15197.3 | D10: ='1. Raw Data - Bloomberg'!E260 -> 16844.1 | E10: ='1. Raw Data - Bloomberg'!F260 -> 17650.7 | F10: ='1. Raw Data - Bloomberg'!G260 -> 19690.3 | G10: ='1. Raw Data - Bloomberg'!H260 -> 21544.4 | H10: ='1. Raw Data - Bloomberg'!I260 -> 19164.6 | I10: ='1. Raw Data - Bloomberg'!J260 -> 24607 | J10: ='1. Raw Data - Bloomberg'!K260 -> 26576.1 | ... L10: ='1. Raw Data - Bloomberg'!M260 -> 29765.9 | M10: =L10*(1+'3. Historical & Forecast Ratio '!M10) -> 32208.072 | N10: =M10*(1+'3. Historical & Forecast Ratio '!N10) -> 34850.615 | O10: =N10*(1+'3. Historical & Forecast Ratio '!O10) -> 37709.968 | P10: =O10*(1+'3. Historical & Forecast Ratio '!P10) -> 40803.919 | Q10: =P10*(1+'3. Historical & Forecast Ratio '!Q10) -> 44151.717 | R10: =Q10*(1+'3. Historical & Forecast Ratio '!R10) -> 47774.188 | S10: =R10*(1+'3. Historical & Forecast Ratio '!S10) -> 51693.868 | T10: =S10*(1+'3. Historical & Forecast Ratio '!T10) -> 55935.141 | ... AB10: =AA10*(1+'3. Historical & Forecast Ratio '!AB10) -> 105111.56
B11: Licensed Stores | C11: ='1. Raw Data - Bloomberg'!D268 -> 1861.9 | D11: ='1. Raw Data - Bloomberg'!E268 -> 2154.2 | E11: ='1. Raw Data - Bloomberg'!F268 -> 2355 | F11: ='1. Raw Data - Bloomberg'!G268 -> 2652.2 | G11: ='1. Raw Data - Bloomberg'!H268 -> 2875 | H11: ='1. Raw Data - Bloomberg'!I268 -> 2327.1 | I11: ='1. Raw Data - Bloomberg'!J268 -> 2683.6 | J11: ='1. Raw Data - Bloomberg'!K268 -> 3655.5 | ... L11: ='1. Raw Data - Bloomberg'!M268 -> 4505.1 | M11: =L11*(1+'3. Historical & Forecast Ratio '!M11) -> 5014.6791 | N11: =M11*(1+'3. Historical & Forecast Ratio '!N11) -> 5581.8974 | O11: =N11*(1+'3. Historical & Forecast Ratio '!O11) -> 6213.2748 | P11: =O11*(1+'3. Historical & Forecast Ratio '!P11) -> 6916.0682 | Q11: =P11*(1+'3. Historical & Forecast Ratio '!Q11) -> 7698.3557 | R11: =Q11*(1+'3. Historical & Forecast Ratio '!R11) -> 8569.129 | S11: =R11*(1+'3. Historical & Forecast Ratio '!S11) -> 9538.3969 | T11: =S11*(1+'3. Historical & Forecast Ratio '!T11) -> 10617.3 | ... AB11: =AA11*(1+'3. Historical & Forecast Ratio '!AB11) -> 25022.1
B12: CPG, Foodservice and Other | C12: ='1. Raw Data - Bloomberg'!D270 -> 2103.5 | D12: ='1. Raw Data - Bloomberg'!E270 -> 2317.6 | E12: ='1. Raw Data - Bloomberg'!F270 -> 2381.1 | F12: ='1. Raw Data - Bloomberg'!G270 -> 2377 | G12: ='1. Raw Data - Bloomberg'!H270 -> 2089.2 | H12: ='1. Raw Data - Bloomberg'!I270 -> 2026.3 | I12: ='1. Raw Data - Bloomberg'!J270 -> 1770 | J12: ='1. Raw Data - Bloomberg'!K270 -> 2018.7 | ... L12: ='1. Raw Data - Bloomberg'!M270 -> 1905.2 | M12: =L12*(1+'3. Historical & Forecast Ratio '!M12) -> 1891.1535 | N12: =M12*(1+'3. Historical & Forecast Ratio '!N12) -> 1877.2106 | O12: =N12*(1+'3. Historical & Forecast Ratio '!O12) -> 1863.3704 | P12: =O12*(1+'3. Historical & Forecast Ratio '!P12) -> 1849.6324 | Q12: =P12*(1+'3. Historical & Forecast Ratio '!Q12) -> 1835.9955 | R12: =Q12*(1+'3. Historical & Forecast Ratio '!R12) -> 1822.4593 | S12: =R12*(1+'3. Historical & Forecast Ratio '!S12) -> 1809.0228 | T12: =S12*(1+'3. Historical & Forecast Ratio '!T12) -> 1795.6854 | ... AB12: =AA12*(1+'3. Historical & Forecast Ratio '!AB12) -> 1692.4659
B13: COGS | C13: ='1. Raw Data - Bloomberg'!D9 -> 13198.6 | D13: ='1. Raw Data - Bloomberg'!E9 -> 14573.3 | E13: ='1. Raw Data - Bloomberg'!F9 -> 15552.2 | F13: ='1. Raw Data - Bloomberg'!G9 -> 17402.9 | G13: ='1. Raw Data - Bloomberg'!H9 -> 19020.5 | H13: ='1. Raw Data - Bloomberg'!I9 -> 18458.9 | I13: ='1. Raw Data - Bloomberg'!J9 -> 20652 | J13: ='1. Raw Data - Bloomberg'!K9 -> 23879.2 | ... L13: ='1. Raw Data - Bloomberg'!M9 -> 26467.1 | M13: =M9*'3. Historical & Forecast Ratio '!M13 -> 28093.89 | N13: =N9*'3. Historical & Forecast Ratio '!N13 -> 30389.313 | O13: =O9*'3. Historical & Forecast Ratio '!O13 -> 32886.619 | P13: =P9*'3. Historical & Forecast Ratio '!P13 -> 35603.795 | Q13: =Q9*'3. Historical & Forecast Ratio '!Q13 -> 38560.468 | R13: =R9*'3. Historical & Forecast Ratio '!R13 -> 41778.056 | S13: =S9*'3. Historical & Forecast Ratio '!S13 -> 45279.933 | T13: =T9*'3. Historical & Forecast Ratio '!T13 -> 49091.615 | ... AB13: =AB9*'3. Historical & Forecast Ratio '!AB13 -> 94685.216
B15: Gross Profit | C15: =C9-C13 -> 5964.1 | D15: =D9-D13 -> 6742.6 | E15: =E9-E13 -> 6834.6 | F15: =F9-F13 -> 7316.6 | G15: =G9-G13 -> 7488.1 | H15: =H9-H13 -> 5059.1 | I15: =I9-I13 -> 8408.6 | J15: =J9-J13 -> 8371.1 | ... AB15: =AB9-AB13 -> 37140.905
B17: Other Operating Income | C17: ='1. Raw Data - Bloomberg'!D11 -> 0 | D17: ='1. Raw Data - Bloomberg'!E11 -> 318.2 | E17: ='1. Raw Data - Bloomberg'!F11 -> 391.4 | F17: ='1. Raw Data - Bloomberg'!G11 -> 301.2 | G17: ='1. Raw Data - Bloomberg'!H11 -> 298 | H17: ='1. Raw Data - Bloomberg'!I11 -> 322.5 | I17: ='1. Raw Data - Bloomberg'!J11 -> 385.3 | J17: ='1. Raw Data - Bloomberg'!K11 -> 234.1 | ... L17: ='1. Raw Data - Bloomberg'!M11 -> 301.2
B19: SG&A | C19: ='1. Raw Data - Bloomberg'!D13 -> 1424.6 | D19: ='1. Raw Data - Bloomberg'!E13 -> 1657.5 | E19: ='1. Raw Data - Bloomberg'!F13 -> 1691 | F19: ='1. Raw Data - Bloomberg'!G13 -> 1968.5 | G19: ='1. Raw Data - Bloomberg'!H13 -> 2029 | H19: ='1. Raw Data - Bloomberg'!I13 -> 1922.2 | I19: ='1. Raw Data - Bloomberg'!J13 -> 2215.5 | J19: ='1. Raw Data - Bloomberg'!K13 -> 2448.7 | ... L19: ='1. Raw Data - Bloomberg'!M13 -> 2523.3 | M19: =L19*(1+'3. Historical & Forecast Ratio '!M17) -> 2703.7752 | N19: =M19*(1+'3. Historical & Forecast Ratio '!N17) -> 2897.1586 | O19: =N19*(1+'3. Historical & Forecast Ratio '!O17) -> 3104.3735 | P19: =O19*(1+'3. Historical & Forecast Ratio '!P17) -> 3326.4091 | Q19: =P19*(1+'3. Historical & Forecast Ratio '!Q17) -> 3564.3254 | R19: =Q19*(1+'3. Historical & Forecast Ratio '!R17) -> 3819.2583 | S19: =R19*(1+'3. Historical & Forecast Ratio '!S17) -> 4092.425 | T19: =S19*(1+'3. Historical & Forecast Ratio '!T17) -> 4385.1295 | ... AB19: =AA19*(1+'3. Historical & Forecast Ratio '!AB17) -> 7620.7191
B20: Depreciation & Amortization | C20: ='1. Raw Data - Bloomberg'!D17 -> 893.9 | D20: ='1. Raw Data - Bloomberg'!E17 -> 980.8 | E20: ='1. Raw Data - Bloomberg'!F17 -> 1011.4 | F20: ='1. Raw Data - Bloomberg'!G17 -> 1247 | G20: ='1. Raw Data - Bloomberg'!H17 -> 1377.3 | H20: ='1. Raw Data - Bloomberg'!I17 -> 1431.3 | I20: ='1. Raw Data - Bloomberg'!J17 -> 1441.7 | J20: ='1. Raw Data - Bloomberg'!K17 -> 1447.9 | ... L20: ='1. Raw Data - Bloomberg'!M17 -> 1512.6 | M20: =L20*(1+'3. Historical & Forecast Ratio '!M18) -> 1608.0271 | N20: =M20*(1+'3. Historical & Forecast Ratio '!N18) -> 1709.4745 | O20: =N20*(1+'3. Historical & Forecast Ratio '!O18) -> 1817.3221 | P20: =O20*(1+'3. Historical & Forecast Ratio '!P18) -> 1931.9735 | Q20: =P20*(1+'3. Historical & Forecast Ratio '!Q18) -> 2053.8581 | R20: =Q20*(1+'3. Historical & Forecast Ratio '!R18) -> 2183.4322 | S20: =R20*(1+'3. Historical & Forecast Ratio '!S18) -> 2321.1809 | T20: =S20*(1+'3. Historical & Forecast Ratio '!T18) -> 2467.6198 | ... AB20: =AA20*(1+'3. Historical & Forecast Ratio '!AB18) -> 4025.6166
B21: Other Operating Expenses | C21: ='1. Raw Data - Bloomberg'!D18 -> -10 | D21: ='1. Raw Data - Bloomberg'!E18 -> 250.6 | E21: ='1. Raw Data - Bloomberg'!F18 -> 172.4 | F21: ='1. Raw Data - Bloomberg'!G18 -> -92.7 | G21: ='1. Raw Data - Bloomberg'!H18 -> -190.7 | H21: ='1. Raw Data - Bloomberg'!I18 -> -105.1 | I21: ='1. Raw Data - Bloomberg'!J18 -> -81.2 | J21: ='1. Raw Data - Bloomberg'!K18 -> -146.4 | ... L21: ='1. Raw Data - Bloomberg'!M18 -> 444.1 | M21: =L21*(1+'3. Historical & Forecast Ratio '!M19) -> -288.30237 | N21: =M21*(1+'3. Historical & Forecast Ratio '!N19) -> 187.16113 | O21: =N21*(1+'3. Historical & Forecast Ratio '!O19) -> -121.50191 | P21: =O21*(1+'3. Historical & Forecast Ratio '!P19) -> 78.877026 | Q21: =P21*(1+'3. Historical & Forecast Ratio '!Q19) -> -51.20566 | R21: =Q21*(1+'3. Historical & Forecast Ratio '!R19) -> 33.241867 | S21: =R21*(1+'3. Historical & Forecast Ratio '!S19) -> -21.58007 | T21: =S21*(1+'3. Historical & Forecast Ratio '!T19) -> 14.009424 | ... AB21: =AA21*(1+'3. Historical & Forecast Ratio '!AB19) -> 0.44193641
B22: Total Operating Expenses | C22: =C19+C21+C20 -> 2308.5 | D22: =D19+D21+D20 -> 2888.9 | E22: =E19+E21+E20 -> 2874.8 | F22: =F19+F21+F20 -> 3122.8 | G22: =G19+G21+G20 -> 3215.6 | H22: =H19+H21+H20 -> 3248.4 | I22: =I19+I21+I20 -> 3576 | J22: =J19+J21+J20 -> 3750.2 | ... AB22: =AB19+AB21+AB20 -> 11646.778
B24: EBIT | C24: =C15+C17-C22 -> 3655.6 | D24: =D15+D17-D22 -> 4171.9 | E24: =E15+E17-E22 -> 4351.2 | F24: =F15+F17-F22 -> 4495 | G24: =G15+G17-G22 -> 4570.5 | H24: =H15+H17-H22 -> 2133.2 | I24: =I15+I17-I22 -> 5217.9 | J24: =J15+J17-J22 -> 4855 | ... L24: =L15+L17-L22 -> 5530.3 | M24: =M15-M22 -> 6996.5151 | N24: =N15-N22 -> 7126.6158 | O24: =O15-O22 -> 8099.801 | P24: =P15-P22 -> 8628.5655 | Q24: =Q15-Q22 -> 9558.622 | R24: =R15-R22 -> 10351.788 | S24: =S15-S22 -> 11369.329 | T24: =T15-T22 -> 12389.753 | ... AB24: =AB15-AB22 -> 25494.128
B26: Interest Income | C26: ='1. Raw Data - Bloomberg'!D23 -> 0 | D26: ='1. Raw Data - Bloomberg'!E23 -> 0 | E26: ='1. Raw Data - Bloomberg'!F23 -> 0 | F26: ='1. Raw Data - Bloomberg'!G23 -> 0 | G26: ='1. Raw Data - Bloomberg'!H23 -> 0 | H26: ='1. Raw Data - Bloomberg'!I23 -> 0 | I26: ='1. Raw Data - Bloomberg'!J23 -> 0 | J26: ='1. Raw Data - Bloomberg'!K23 -> 0 | ... L26: ='1. Raw Data - Bloomberg'!M23 -> 0 | M26: =AVERAGE($C26:$L26) -> 0 | N26: =AVERAGE($C26:$L26) -> 0 | O26: =AVERAGE($C26:$L26) -> 0 | P26: =AVERAGE($C26:$L26) -> 0 | Q26: =AVERAGE($C26:$L26) -> 0 | R26: =AVERAGE($C26:$L26) -> 0 | S26: =AVERAGE($C26:$L26) -> 0 | T26: =AVERAGE($C26:$L26) -> 0 | ... AB26: =AVERAGE($C26:$L26) -> 0
B27: Interest Expense | C27: ='1. Raw Data - Bloomberg'!D22 -> 70.5 | D27: ='1. Raw Data - Bloomberg'!E22 -> 81.3 | E27: ='1. Raw Data - Bloomberg'!F22 -> 92.5 | F27: ='1. Raw Data - Bloomberg'!G22 -> 170.3 | G27: ='1. Raw Data - Bloomberg'!H22 -> 331 | H27: ='1. Raw Data - Bloomberg'!I22 -> 437 | I27: ='1. Raw Data - Bloomberg'!J22 -> 469.8 | J27: ='1. Raw Data - Bloomberg'!K22 -> 482.9 | ... L27: ='1. Raw Data - Bloomberg'!M22 -> 562 | M27: =AVERAGE($C27:$L27) -> 324.74 | N27: =AVERAGE($C27:$L27) -> 324.74 | O27: =AVERAGE($C27:$L27) -> 324.74 | P27: =AVERAGE($C27:$L27) -> 324.74 | Q27: =AVERAGE($C27:$L27) -> 324.74 | R27: =AVERAGE($C27:$L27) -> 324.74 | S27: =AVERAGE($C27:$L27) -> 324.74 | T27: =AVERAGE($C27:$L27) -> 324.74 | ... AB27: =AVERAGE($C27:$L27) -> 324.74
B28: Net Interest Expense | C28: =C27-C26 -> 70.5 | D28: =D27-D26 -> 81.3 | E28: =E27-E26 -> 92.5 | F28: =F27-F26 -> 170.3 | G28: =G27-G26 -> 331 | H28: =H27-H26 -> 437 | I28: =I27-I26 -> 469.8 | J28: =J27-J26 -> 482.9 | ... AB28: =AB27-AB26 -> 324.74
B29: Other Non-Op (Income) Loss | C29: ='1. Raw Data - Bloomberg'!D25 -> -43 | D29: ='1. Raw Data - Bloomberg'!E25 -> -102.6 | E29: ='1. Raw Data - Bloomberg'!F25 -> -181.8 | F29: ='1. Raw Data - Bloomberg'!G25 -> -191.4 | G29: ='1. Raw Data - Bloomberg'!H25 -> -96.5 | H29: ='1. Raw Data - Bloomberg'!I25 -> -39.7 | I29: ='1. Raw Data - Bloomberg'!J25 -> -90.1 | J29: ='1. Raw Data - Bloomberg'!K25 -> -97 | ... L29: ='1. Raw Data - Bloomberg'!M25 -> -122.8 | M29: =AVERAGE($C29:$L29) -> -104.61 | N29: =AVERAGE($C29:$L29) -> -104.61 | O29: =AVERAGE($C29:$L29) -> -104.61 | P29: =AVERAGE($C29:$L29) -> -104.61 | Q29: =AVERAGE($C29:$L29) -> -104.61 | R29: =AVERAGE($C29:$L29) -> -104.61 | S29: =AVERAGE($C29:$L29) -> -104.61 | T29: =AVERAGE($C29:$L29) -> -104.61 | ... AB29: =AVERAGE($C29:$L29) -> -104.61
B31: Non-Operating (Income) Loss | C31: =SUM(C28:C29) -> 27.5 | D31: =SUM(D28:D29) -> -21.3 | E31: =SUM(E28:E29) -> -89.3 | F31: =SUM(F28:F29) -> -21.1 | G31: =SUM(G28:G29) -> 234.5 | H31: =SUM(H28:H29) -> 397.3 | I31: =SUM(I28:I29) -> 379.7 | J31: =SUM(J28:J29) -> 385.9 | ... AB31: =SUM(AB28:AB29) -> 220.13
B33: EBT | C33: =C24-C31 -> 3628.1 | D33: =D24-D31 -> 4193.2 | E33: =E24-E31 -> 4440.5 | F33: =F24-F31 -> 4516.1 | G33: =G24-G31 -> 4336 | H33: =H24-H31 -> 1735.9 | I33: =I24-I31 -> 4838.2 | J33: =J24-J31 -> 4469.1 | ... L33: =L24-L31 -> 5091.1 | M33: =M24-M28 -> 6671.7751 | N33: =N24-N28 -> 6801.8758 | O33: =O24-O28 -> 7775.061 | P33: =P24-P28 -> 8303.8255 | Q33: =Q24-Q28 -> 9233.882 | R33: =R24-R28 -> 10027.048 | S33: =S24-S28 -> 11044.589 | T33: =T24-T28 -> 12065.013 | ... AB33: =AB24-AB28 -> 25169.388
B35: Abnormal Loss/Gains | C35: ='1. Raw Data - Bloomberg'!D27 -> -274.9 | D35: ='1. Raw Data - Bloomberg'!E27 -> -5.4 | E35: ='1. Raw Data - Bloomberg'!F27 -> 123 | F35: ='1. Raw Data - Bloomberg'!G27 -> -1263.9 | G35: ='1. Raw Data - Bloomberg'!H27 -> -130.2 | H35: ='1. Raw Data - Bloomberg'!I27 -> 571.5 | I35: ='1. Raw Data - Bloomberg'!J27 -> -518.7 | J35: ='1. Raw Data - Bloomberg'!K27 -> 237.2 | ... L35: ='1. Raw Data - Bloomberg'!M27 -> 121.5 | M35: =AVERAGE($C35:$L35) -> -120.93 | N35: =AVERAGE($C35:$L35) -> -120.93 | O35: =AVERAGE($C35:$L35) -> -120.93 | P35: =AVERAGE($C35:$L35) -> -120.93 | Q35: =AVERAGE($C35:$L35) -> -120.93 | R35: =AVERAGE($C35:$L35) -> -120.93 | S35: =AVERAGE($C35:$L35) -> -120.93 | T35: =AVERAGE($C35:$L35) -> -120.93 | ... AB35: =AVERAGE($C35:$L35) -> -120.93
B37: Adj EBT | C37: =C33-C35 -> 3903 | D37: =D33-D35 -> 4198.6 | E37: =E33-E35 -> 4317.5 | F37: =F33-F35 -> 5780 | G37: =G33-G35 -> 4466.2 | H37: =H33-H35 -> 1164.4 | I37: =I33-I35 -> 5356.9 | J37: =J33-J35 -> 4231.9 | ... AB37: =AB33-AB35 -> 25290.318
B39: Income Tax Expense / Benefit | C39: ='1. Raw Data - Bloomberg'!D38 -> 1143.7 | D39: ='1. Raw Data - Bloomberg'!E38 -> 1379.7 | E39: ='1. Raw Data - Bloomberg'!F38 -> 1432.6 | F39: ='1. Raw Data - Bloomberg'!G38 -> 1262 | G39: ='1. Raw Data - Bloomberg'!H38 -> 871.6 | H39: ='1. Raw Data - Bloomberg'!I38 -> 239.7 | I39: ='1. Raw Data - Bloomberg'!J38 -> 1156.6 | J39: ='1. Raw Data - Bloomberg'!K38 -> 948.5 | ... L39: ='1. Raw Data - Bloomberg'!M38 -> 1207.3 | M39: =M37*'3. Historical & Forecast Ratio '!M22 -> 1493.1945 | N39: =N37*'3. Historical & Forecast Ratio '!N22 -> 1521.7937 | O39: =O37*'3. Historical & Forecast Ratio '!O22 -> 1735.7224 | P39: =P37*'3. Historical & Forecast Ratio '!P22 -> 1851.9571 | Q39: =Q37*'3. Historical & Forecast Ratio '!Q22 -> 2056.4052 | R39: =R37*'3. Historical & Forecast Ratio '!R22 -> 2230.7614 | S39: =S37*'3. Historical & Forecast Ratio '!S22 -> 2454.4406 | T39: =T37*'3. Historical & Forecast Ratio '!T22 -> 2678.7537 | ... AB39: =AB37*'3. Historical & Forecast Ratio '!AB22 -> 5559.3999
B41: Net Profit | C41: =C37-C39 -> 2759.3 | D41: =D37-D39 -> 2818.9 | E41: =E37-E39 -> 2884.9 | F41: =F37-F39 -> 4518 | G41: =G37-G39 -> 3594.6 | H41: =H37-H39 -> 924.7 | I41: =I37-I39 -> 4200.3 | J41: =J37-J39 -> 3283.4 | ... AB41: =AB37-AB39 -> 19730.918
B43: Minority Interest | C43: ='1. Raw Data - Bloomberg'!D46 -> 1.9 | D43: ='1. Raw Data - Bloomberg'!E46 -> 1.2 | E43: ='1. Raw Data - Bloomberg'!F46 -> 0.2 | F43: ='1. Raw Data - Bloomberg'!G46 -> -0.3 | G43: ='1. Raw Data - Bloomberg'!H46 -> -4.6 | H43: ='1. Raw Data - Bloomberg'!I46 -> -3.6 | I43: ='1. Raw Data - Bloomberg'!J46 -> 1 | J43: ='1. Raw Data - Bloomberg'!K46 -> 1.8 | ... L43: ='1. Raw Data - Bloomberg'!M46 -> 1.4 | M43: =AVERAGE($C43:$L43) -> -0.08 | N43: =AVERAGE($C43:$L43) -> -0.08 | O43: =AVERAGE($C43:$L43) -> -0.08 | P43: =AVERAGE($C43:$L43) -> -0.08 | Q43: =AVERAGE($C43:$L43) -> -0.08 | R43: =AVERAGE($C43:$L43) -> -0.08 | S43: =AVERAGE($C43:$L43) -> -0.08 | T43: =AVERAGE($C43:$L43) -> -0.08 | ... AB43: =AVERAGE($C43:$L43) -> -0.08
B45: Net Income, GAAP | C45: =C41-C43 -> 2757.4 | D45: =D41-D43 -> 2817.7 | E45: =E41-E43 -> 2884.7 | F45: =F41-F43 -> 4518.3 | G45: =G41-G43 -> 3599.2 | H45: =H41-H43 -> 928.3 | I45: =I41-I43 -> 4199.3 | J45: =J41-J43 -> 3281.6 | ... AB45: =AB41-AB43 -> 19730.998
B47: Interest Tax Shield | C47: =C28*'3. Historical & Forecast Ratio '!C22 -> 20.658686 | D47: =D28*'3. Historical & Forecast Ratio '!D22 -> 26.715955 | E47: =E28*'3. Historical & Forecast Ratio '!E22 -> 30.692646 | F47: =F28*'3. Historical & Forecast Ratio '!F22 -> 37.183149 | G47: =G28*'3. Historical & Forecast Ratio '!G22 -> 64.596212 | H47: =H28*'3. Historical & Forecast Ratio '!H22 -> 89.95955 | I47: =I28*'3. Historical & Forecast Ratio '!I22 -> 101.43379 | J47: =J28*'3. Historical & Forecast Ratio '!J22 -> 108.23286 | ... AB47: =AB28*'3. Historical & Forecast Ratio '!AB22 -> 71.385403
B48: Operating Taxes | C48: =C39+C47 -> 1164.3587 | D48: =D39+D47 -> 1406.416 | E48: =E39+E47 -> 1463.2926 | F48: =F39+F47 -> 1299.1831 | G48: =G39+G47 -> 936.19621 | H48: =H39+H47 -> 329.65955 | I48: =I39+I47 -> 1258.0338 | J48: =J39+J47 -> 1056.7329 | ... AB48: =AB39+AB47 -> 5630.7853
B50: NOPLAT | C50: =C24+C48 -> 4819.9587 | D50: =D24+D48 -> 5578.316 | E50: =E24+E48 -> 5814.4926 | F50: =F24+F48 -> 5794.1831 | G50: =G24+G48 -> 5506.6962 | H50: =H24+H48 -> 2462.8595 | I50: =I24+I48 -> 6475.9338 | J50: =J24+J48 -> 5911.7329 | ... AB50: =AB24+AB48 -> 31124.913
B52: BALANCE SHEET
B53: PARTICULARS | C53: ACTUALS | M53: NEAR TERM FORECAST | R53: FAR TERM FORECAST | AB53: CV
C54: =2015 -> 2015 | D54: =C54+1 -> 2016 | E54: =D54+1 -> 2017 | F54: =E54+1 -> 2018 | G54: =F54+1 -> 2019 | H54: =G54+1 -> 2020 | I54: =H54+1 -> 2021 | J54: =I54+1 -> 2022 | K54: =J54+1 -> 2023 | ... BV54: =BU54+1 -> 2086
C55: ="FY "&C54 -> FY 2015 | D55: ="FY "&D54 -> FY 2016 | E55: ="FY "&E54 -> FY 2017 | F55: ="FY "&F54 -> FY 2018 | G55: ="FY "&G54 -> FY 2019 | H55: ="FY "&H54 -> FY 2020 | I55: ="FY "&I54 -> FY 2021 | J55: ="FY "&J54 -> FY 2022 | ... AA55: ="FY "&AA54 -> FY 2039 | AB55: Perpetuity
B56: ASSETS:
B57: Operating Current Assets | C57: ='1. Raw Data - Bloomberg'!D104 -> 3971 | D57: ='1. Raw Data - Bloomberg'!E104 -> 4760.5 | E57: ='1. Raw Data - Bloomberg'!F104 -> 5283.4 | F57: ='1. Raw Data - Bloomberg'!G104 -> 12494.2 | G57: ='1. Raw Data - Bloomberg'!H104 -> 5653.9 | H57: ='1. Raw Data - Bloomberg'!I104 -> 7806.4 | I57: ='1. Raw Data - Bloomberg'!J104 -> 9756.4 | J57: ='1. Raw Data - Bloomberg'!K104 -> 7018.7 | ... L57: ='1. Raw Data - Bloomberg'!M104 -> 6847.4
B58: Operating Current Liabilities | C58: ='1. Raw Data - Bloomberg'!D137 -> 3648.1 | D58: ='1. Raw Data - Bloomberg'!E137 -> 4546.9 | E58: ='1. Raw Data - Bloomberg'!F137 -> 4220.7 | F58: ='1. Raw Data - Bloomberg'!G137 -> 5684.2 | G58: ='1. Raw Data - Bloomberg'!H137 -> 6168.7 | H58: ='1. Raw Data - Bloomberg'!I137 -> 7346.8 | I58: ='1. Raw Data - Bloomberg'!J137 -> 8151.4 | J58: ='1. Raw Data - Bloomberg'!K137 -> 9151.8 | ... L58: ='1. Raw Data - Bloomberg'!M137 -> 9070
B59: Net Operating Working Capital | C59: =C57-C58 -> 322.9 | D59: =D57-D58 -> 213.6 | E59: =E57-E58 -> 1062.7 | F59: =F57-F58 -> 6810 | G59: =G57-G58 -> -514.8 | H59: =H57-H58 -> 459.6 | I59: =I57-I58 -> 1605 | J59: =J57-J58 -> -2133.1 | ... L59: =L57-L58 -> -2222.6 | M59: =M9*'3. Historical & Forecast Ratio '!M29 -> 863.81395 | N59: =N9*'3. Historical & Forecast Ratio '!N29 -> 934.39223 | O59: =O9*'3. Historical & Forecast Ratio '!O29 -> 1011.1779 | P59: =P9*'3. Historical & Forecast Ratio '!P29 -> 1094.724 | Q59: =Q9*'3. Historical & Forecast Ratio '!Q29 -> 1185.634 | R59: =R9*'3. Historical & Forecast Ratio '!R29 -> 1284.5664 | S59: =S9*'3. Historical & Forecast Ratio '!S29 -> 1392.24 | T59: =T9*'3. Historical & Forecast Ratio '!T29 -> 1509.4393 | ... AB59: =AB9*'3. Historical & Forecast Ratio '!AB29 -> 2911.3238
...

Sheet 3. Historical & Forecast Ratio 
B2: Historical & Forecast Ratio - Starbucks US
B5: INCOME STATEMENT
B6: PARTICULARS | C6: ACTUALS | M6: NEAR TERM FORECAST | R6: FAR TERM FORECAST | AB6: CV
C7: =2015 -> 2015 | D7: =C7+1 -> 2016 | E7: =D7+1 -> 2017 | F7: =E7+1 -> 2018 | G7: =F7+1 -> 2019 | H7: =G7+1 -> 2020 | I7: =H7+1 -> 2021 | J7: =I7+1 -> 2022 | K7: =J7+1 -> 2023 | ... BV7: =BU7+1 -> 2086
C8: ="FY "&C7 -> FY 2015 | D8: ="FY "&D7 -> FY 2016 | E8: ="FY "&E7 -> FY 2017 | F8: ="FY "&F7 -> FY 2018 | G8: ="FY "&G7 -> FY 2019 | H8: ="FY "&H7 -> FY 2020 | I8: ="FY "&I7 -> FY 2021 | J8: ="FY "&J7 -> FY 2022 | ... AA8: ="FY "&AA7 -> FY 2039 | AB8: Perpetuity
B9: Revenue % YoY | D9: =('2. Integrated Finance'!D9-'2. Integrated Finance'!C9)/'2. Integrated Finance'!C9 -> 0.11236412 | E9: =('2. Integrated Finance'!E9-'2. Integrated Finance'!D9)/'2. Integrated Finance'!D9 -> 0.050239493 | F9: =('2. Integrated Finance'!F9-'2. Integrated Finance'!E9)/'2. Integrated Finance'!E9 -> 0.1041998 | G9: =('2. Integrated Finance'!G9-'2. Integrated Finance'!F9)/'2. Integrated Finance'!F9 -> 0.072376059 | H9: =('2. Integrated Finance'!H9-'2. Integrated Finance'!G9)/'2. Integrated Finance'!G9 -> -0.11281622 | I9: =('2. Integrated Finance'!I9-'2. Integrated Finance'!H9)/'2. Integrated Finance'!H9 -> 0.2356748 | J9: =('2. Integrated Finance'!J9-'2. Integrated Finance'!I9)/'2. Integrated Finance'!I9 -> 0.10976029 | K9: =('2. Integrated Finance'!K9-'2. Integrated Finance'!J9)/'2. Integrated Finance'!J9 -> 0.1155121 | L9: =('2. Integrated Finance'!L9-'2. Integrated Finance'!K9)/'2. Integrated Finance'!K9 -> 0.0055760015 | M9: =AVERAGE($C9:$L9) -> 0.076987384 | N9: =AVERAGE($C9:$L9) -> 0.076987384 | O9: =AVERAGE($C9:$L9) -> 0.076987384 | P9: =AVERAGE($C9:$L9) -> 0.076987384 | Q9: =AVERAGE($C9:$L9) -> 0.076987384 | R9: =AVERAGE($C9:$L9) -> 0.076987384 | S9: =AVERAGE($C9:$L9) -> 0.076987384 | T9: =AVERAGE($C9:$L9) -> 0.076987384 | ... AB9: =AVERAGE($C9:$L9) -> 0.076987384
B10: Company Operated Retail % YoY | D10: =('2. Integrated Finance'!D10-'2. Integrated Finance'!C10)/'2. Integrated Finance'!C10 -> 0.10836135 | E10: =('2. Integrated Finance'!E10-'2. Integrated Finance'!D10)/'2. Integrated Finance'!D10 -> 0.047886203 | F10: =('2. Integrated Finance'!F10-'2. Integrated Finance'!E10)/'2. Integrated Finance'!E10 -> 0.11555349 | G10: =('2. Integrated Finance'!G10-'2. Integrated Finance'!F10)/'2. Integrated Finance'!F10 -> 0.094163116 | H10: =('2. Integrated Finance'!H10-'2. Integrated Finance'!G10)/'2. Integrated Finance'!G10 -> -0.11046026 | I10: =('2. Integrated Finance'!I10-'2. Integrated Finance'!H10)/'2. Integrated Finance'!H10 -> 0.28398193 | J10: =('2. Integrated Finance'!J10-'2. Integrated Finance'!I10)/'2. Integrated Finance'!I10 -> 0.080021945 | K10: =('2. Integrated Finance'!K10-'2. Integrated Finance'!J10)/'2. Integrated Finance'!J10 -> 0.10860134 | L10: =('2. Integrated Finance'!L10-'2. Integrated Finance'!K10)/'2. Integrated Finance'!K10 -> 0.010304694 | M10: =AVERAGE($C10:$L10) -> 0.082045979 | N10: =AVERAGE($C10:$L10) -> 0.082045979 | O10: =AVERAGE($C10:$L10) -> 0.082045979 | P10: =AVERAGE($C10:$L10) -> 0.082045979 | Q10: =AVERAGE($C10:$L10) -> 0.082045979 | R10: =AVERAGE($C10:$L10) -> 0.082045979 | S10: =AVERAGE($C10:$L10) -> 0.082045979 | T10: =AVERAGE($C10:$L10) -> 0.082045979 | ... AB10: =AVERAGE($C10:$L10) -> 0.082045979
B11: Licensed Stores % YoY | D11: =('2. Integrated Finance'!D11-'2. Integrated Finance'!C11)/'2. Integrated Finance'!C11 -> 0.15699017 | E11: =('2. Integrated Finance'!E11-'2. Integrated Finance'!D11)/'2. Integrated Finance'!D11 -> 0.093213258 | F11: =('2. Integrated Finance'!F11-'2. Integrated Finance'!E11)/'2. Integrated Finance'!E11 -> 0.12619958 | G11: =('2. Integrated Finance'!G11-'2. Integrated Finance'!F11)/'2. Integrated Finance'!F11 -> 0.084005731 | H11: =('2. Integrated Finance'!H11-'2. Integrated Finance'!G11)/'2. Integrated Finance'!G11 -> -0.19057391 | I11: =('2. Integrated Finance'!I11-'2. Integrated Finance'!H11)/'2. Integrated Finance'!H11 -> 0.15319496 | J11: =('2. Integrated Finance'!J11-'2. Integrated Finance'!I11)/'2. Integrated Finance'!I11 -> 0.36216277 | K11: =('2. Integrated Finance'!K11-'2. Integrated Finance'!J11)/'2. Integrated Finance'!J11 -> 0.23449596 | L11: =('2. Integrated Finance'!L11-'2. Integrated Finance'!K11)/'2. Integrated Finance'!K11 -> -0.0016841359 | M11: =AVERAGE($C$11:$L$11) -> 0.1131116 | N11: =AVERAGE($C$11:$L$11) -> 0.1131116 | O11: =AVERAGE($C$11:$L$11) -> 0.1131116 | P11: =AVERAGE($C$11:$L$11) -> 0.1131116 | Q11: =AVERAGE($C$11:$L$11) -> 0.1131116 | R11: =AVERAGE($C$11:$L$11) -> 0.1131116 | S11: =AVERAGE($C$11:$L$11) -> 0.1131116 | T11: =AVERAGE($C$11:$L$11) -> 0.1131116 | ... AB11: =AVERAGE($C$11:$L$11) -> 0.1131116
B12: CPG, Foodservice and Other % YoY | D12: =('2. Integrated Finance'!D12-'2. Integrated Finance'!C12)/'2. Integrated Finance'!C12 -> 0.10178274 | E12: =('2. Integrated Finance'!E12-'2. Integrated Finance'!D12)/'2. Integrated Finance'!D12 -> 0.027399033 | F12: =('2. Integrated Finance'!F12-'2. Integrated Finance'!E12)/'2. Integrated Finance'!E12 -> -0.0017218932 | G12: =('2. Integrated Finance'!G12-'2. Integrated Finance'!F12)/'2. Integrated Finance'!F12 -> -0.12107699 | H12: =('2. Integrated Finance'!H12-'2. Integrated Finance'!G12)/'2. Integrated Finance'!G12 -> -0.030107218 | I12: =('2. Integrated Finance'!I12-'2. Integrated Finance'!H12)/'2. Integrated Finance'!H12 -> -0.1264867 | J12: =('2. Integrated Finance'!J12-'2. Integrated Finance'!I12)/'2. Integrated Finance'!I12 -> 0.14050847 | K12: =('2. Integrated Finance'!K12-'2. Integrated Finance'!J12)/'2. Integrated Finance'!J12 -> -0.0089661663 | L12: =('2. Integrated Finance'!L12-'2. Integrated Finance'!K12)/'2. Integrated Finance'!K12 -> -0.047685694 | M12: =AVERAGE($C12:$L12) -> -0.0073727121 | N12: =AVERAGE($C12:$L12) -> -0.0073727121 | O12: =AVERAGE($C12:$L12) -> -0.0073727121 | P12: =AVERAGE($C12:$L12) -> -0.0073727121 | Q12: =AVERAGE($C12:$L12) -> -0.0073727121 | R12: =AVERAGE($C12:$L12) -> -0.0073727121 | S12: =AVERAGE($C12:$L12) -> -0.0073727121 | T12: =AVERAGE($C12:$L12) -> -0.0073727121 | ... AB12: =AVERAGE($C12:$L12) -> -0.0073727121
B13: COGS % Revenue | C13: ='2. Integrated Finance'!C13/'2. Integrated Finance'!C9 -> 0.68876515 | D13: ='2. Integrated Finance'!D13/'2. Integrated Finance'!D9 -> 0.68368213 | E13: ='2. Integrated Finance'!E13/'2. Integrated Finance'!E9 -> 0.69470402 | F13: ='2. Integrated Finance'!F13/'2. Integrated Finance'!F9 -> 0.70401505 | G13: ='2. Integrated Finance'!G13/'2. Integrated Finance'!G9 -> 0.71752186 | H13: ='2. Integrated Finance'!H13/'2. Integrated Finance'!H9 -> 0.78488392 | I13: ='2. Integrated Finance'!I13/'2. Integrated Finance'!I9 -> 0.71065291 | J13: ='2. Integrated Finance'!J13/'2. Integrated Finance'!J9 -> 0.74043342 | ... L13: ='2. Integrated Finance'!L13/'2. Integrated Finance'!L9 -> 0.73161637 | M13: =AVERAGE($C13:$L13) -> 0.71825838 | N13: =AVERAGE($C13:$L13) -> 0.71825838 | O13: =AVERAGE($C13:$L13) -> 0.71825838 | P13: =AVERAGE($C13:$L13) -> 0.71825838 | Q13: =AVERAGE($C13:$L13) -> 0.71825838 | R13: =AVERAGE($C13:$L13) -> 0.71825838 | S13: =AVERAGE($C13:$L13) -> 0.71825838 | T13: =AVERAGE($C13:$L13) -> 0.71825838 | ... AB13: =AVERAGE($C13:$L13) -> 0.71825838
B14: Gross Profit Margin | C14: =(1-C13) -> 0.31123485 | D14: =(1-D13) -> 0.31631787 | E14: =(1-E13) -> 0.30529598 | F14: =(1-F13) -> 0.29598495 | G14: =(1-G13) -> 0.28247814 | H14: =(1-H13) -> 0.21511608 | I14: =(1-I13) -> 0.28934709 | J14: =(1-J13) -> 0.25956658 | ... AB14: =(1-AB13) -> 0.28174162
B16: Operating Expenses % YoY | D16: =('2. Integrated Finance'!D22-'2. Integrated Finance'!C22)/'2. Integrated Finance'!C22 -> 0.25141867 | E16: =('2. Integrated Finance'!E22-'2. Integrated Finance'!D22)/'2. Integrated Finance'!D22 -> -0.0048807505 | F16: =('2. Integrated Finance'!F22-'2. Integrated Finance'!E22)/'2. Integrated Finance'!E22 -> 0.086266871 | G16: =('2. Integrated Finance'!G22-'2. Integrated Finance'!F22)/'2. Integrated Finance'!F22 -> 0.029716921 | H16: =('2. Integrated Finance'!H22-'2. Integrated Finance'!G22)/'2. Integrated Finance'!G22 -> 0.010200274 | I16: =('2. Integrated Finance'!I22-'2. Integrated Finance'!H22)/'2. Integrated Finance'!H22 -> 0.10084965 | J16: =('2. Integrated Finance'!J22-'2. Integrated Finance'!I22)/'2. Integrated Finance'!I22 -> 0.048713647 | K16: =('2. Integrated Finance'!K22-'2. Integrated Finance'!J22)/'2. Integrated Finance'!J22 -> 0.1581249 | L16: =('2. Integrated Finance'!L22-'2. Integrated Finance'!K22)/'2. Integrated Finance'!K22 -> 0.031497513 | M16: =AVERAGE($C16:$L16) -> 0.079100855 | N16: =AVERAGE($C16:$L16) -> 0.079100855 | O16: =AVERAGE($C16:$L16) -> 0.079100855 | P16: =AVERAGE($C16:$L16) -> 0.079100855 | Q16: =AVERAGE($C16:$L16) -> 0.079100855 | R16: =AVERAGE($C16:$L16) -> 0.079100855 | S16: =AVERAGE($C16:$L16) -> 0.079100855 | T16: =AVERAGE($C16:$L16) -> 0.079100855 | ... AB16: =AVERAGE($C16:$L16) -> 0.079100855
B17: SG&A % YoY | D17: =('2. Integrated Finance'!D19-'2. Integrated Finance'!C19)/'2. Integrated Finance'!C19 -> 0.16348449 | E17: =('2. Integrated Finance'!E19-'2. Integrated Finance'!D19)/'2. Integrated Finance'!D19 -> 0.020211161 | F17: =('2. Integrated Finance'!F19-'2. Integrated Finance'!E19)/'2. Integrated Finance'!E19 -> 0.16410408 | G17: =('2. Integrated Finance'!G19-'2. Integrated Finance'!F19)/'2. Integrated Finance'!F19 -> 0.030734061 | H17: =('2. Integrated Finance'!H19-'2. Integrated Finance'!G19)/'2. Integrated Finance'!G19 -> -0.052636767 | I17: =('2. Integrated Finance'!I19-'2. Integrated Finance'!H19)/'2. Integrated Finance'!H19 -> 0.15258558 | J17: =('2. Integrated Finance'!J19-'2. Integrated Finance'!I19)/'2. Integrated Finance'!I19 -> 0.10525841 | K17: =('2. Integrated Finance'!K19-'2. Integrated Finance'!J19)/'2. Integrated Finance'!J19 -> 0.20435333 | L17: =('2. Integrated Finance'!L19-'2. Integrated Finance'!K19)/'2. Integrated Finance'!K19 -> -0.14438303 | M17: =AVERAGE($C17:$L17) -> 0.071523479 | N17: =AVERAGE($C17:$L17) -> 0.071523479 | O17: =AVERAGE($C17:$L17) -> 0.071523479 | P17: =AVERAGE($C17:$L17) -> 0.071523479 | Q17: =AVERAGE($C17:$L17) -> 0.071523479 | R17: =AVERAGE($C17:$L17) -> 0.071523479 | S17: =AVERAGE($C17:$L17) -> 0.071523479 | T17: =AVERAGE($C17:$L17) -> 0.071523479 | ... AB17: =AVERAGE($C17:$L17) -> 0.071523479
B18: Depreciation & Amortization % YoY | D18: =('2. Integrated Finance'!D20-'2. Integrated Finance'!C20)/'2. Integrated Finance'!C20 -> 0.097214454 | E18: =('2. Integrated Finance'!E20-'2. Integrated Finance'!D20)/'2. Integrated Finance'!D20 -> 0.031199021 | F18: =('2. Integrated Finance'!F20-'2. Integrated Finance'!E20)/'2. Integrated Finance'!E20 -> 0.23294443 | G18: =('2. Integrated Finance'!G20-'2. Integrated Finance'!F20)/'2. Integrated Finance'!F20 -> 0.10449078 | H18: =('2. Integrated Finance'!H20-'2. Integrated Finance'!G20)/'2. Integrated Finance'!G20 -> 0.039207144 | I18: =('2. Integrated Finance'!I20-'2. Integrated Finance'!H20)/'2. Integrated Finance'!H20 -> 0.0072661217 | J18: =('2. Integrated Finance'!J20-'2. Integrated Finance'!I20)/'2. Integrated Finance'!I20 -> 0.0043004786 | K18: =('2. Integrated Finance'!K20-'2. Integrated Finance'!J20)/'2. Integrated Finance'!J20 -> -0.058912908 | L18: =('2. Integrated Finance'!L20-'2. Integrated Finance'!K20)/'2. Integrated Finance'!K20 -> 0.11008366 | M18: =AVERAGE($C18:$L18) -> 0.063088132 | N18: =AVERAGE($C18:$L18) -> 0.063088132 | O18: =AVERAGE($C18:$L18) -> 0.063088132 | P18: =AVERAGE($C18:$L18) -> 0.063088132 | Q18: =AVERAGE($C18:$L18) -> 0.063088132 | R18: =AVERAGE($C18:$L18) -> 0.063088132 | S18: =AVERAGE($C18:$L18) -> 0.063088132 | T18: =AVERAGE($C18:$L18) -> 0.063088132 | ... AB18: =AVERAGE($C18:$L18) -> 0.063088132
B19: Other Operating Expenses % YoY | D19: =('2. Integrated Finance'!D21-'2. Integrated Finance'!C21)/'2. Integrated Finance'!C21 -> -26.06 | E19: =('2. Integrated Finance'!E21-'2. Integrated Finance'!D21)/'2. Integrated Finance'!D21 -> -0.31205108 | F19: =('2. Integrated Finance'!F21-'2. Integrated Finance'!E21)/'2. Integrated Finance'!E21 -> -1.537703 | G19: =('2. Integrated Finance'!G21-'2. Integrated Finance'!F21)/'2. Integrated Finance'!F21 -> 1.0571737 | H19: =('2. Integrated Finance'!H21-'2. Integrated Finance'!G21)/'2. Integrated Finance'!G21 -> -0.44887257 | I19: =('2. Integrated Finance'!I21-'2. Integrated Finance'!H21)/'2. Integrated Finance'!H21 -> -0.22740247 | J19: =('2. Integrated Finance'!J21-'2. Integrated Finance'!I21)/'2. Integrated Finance'!I21 -> 0.80295567 | K19: =('2. Integrated Finance'!K21-'2. Integrated Finance'!J21)/'2. Integrated Finance'!J21 -> -1.2151639 | L19: =('2. Integrated Finance'!L21-'2. Integrated Finance'!K21)/'2. Integrated Finance'!K21 -> 13.098413 | M19: =AVERAGE($C19:$L19) -> -1.6491834 | N19: =AVERAGE($C19:$L19) -> -1.6491834 | O19: =AVERAGE($C19:$L19) -> -1.6491834 | P19: =AVERAGE($C19:$L19) -> -1.6491834 | Q19: =AVERAGE($C19:$L19) -> -1.6491834 | R19: =AVERAGE($C19:$L19) -> -1.6491834 | S19: =AVERAGE($C19:$L19) -> -1.6491834 | T19: =AVERAGE($C19:$L19) -> -1.6491834 | ... AB19: =AVERAGE($C19:$L19) -> -1.6491834
B20: EBITA Margin | C20: ='2. Integrated Finance'!C24/'2. Integrated Finance'!C9 -> 0.19076644 | D20: ='2. Integrated Finance'!D24/'2. Integrated Finance'!D9 -> 0.19571775 | E20: ='2. Integrated Finance'!E24/'2. Integrated Finance'!E9 -> 0.19436454 | F20: ='2. Integrated Finance'!F24/'2. Integrated Finance'!F9 -> 0.18184025 | G20: ='2. Integrated Finance'!G24/'2. Integrated Finance'!G9 -> 0.17241574 | H20: ='2. Integrated Finance'!H24/'2. Integrated Finance'!H9 -> 0.090704992 | I20: ='2. Integrated Finance'!I24/'2. Integrated Finance'!I9 -> 0.17955238 | J20: ='2. Integrated Finance'!J24/'2. Integrated Finance'!J9 -> 0.15054124 | ... AB20: ='2. Integrated Finance'!AB24/'2. Integrated Finance'!AB9 -> 0.19339208
B22: Effective Tax Rate | C22: ='2. Integrated Finance'!C39/'2. Integrated Finance'!C37 -> 0.293031 | D22: ='2. Integrated Finance'!D39/'2. Integrated Finance'!D37 -> 0.32860954 | E22: ='2. Integrated Finance'!E39/'2. Integrated Finance'!E37 -> 0.33181239 | F22: ='2. Integrated Finance'!F39/'2. Integrated Finance'!F37 -> 0.2183391 | G22: ='2. Integrated Finance'!G39/'2. Integrated Finance'!G37 -> 0.19515472 | H22: ='2. Integrated Finance'!H39/'2. Integrated Finance'!H37 -> 0.20585709 | I22: ='2. Integrated Finance'!I39/'2. Integrated Finance'!I37 -> 0.21590845 | J22: ='2. Integrated Finance'!J39/'2. Integrated Finance'!J37 -> 0.224131 | ... L22: ='2. Integrated Finance'!L39/'2. Integrated Finance'!L37 -> 0.24293706 | M22: =AVERAGE($F$22:$L$22) -> 0.21982325 | N22: =AVERAGE($F$22:$L$22) -> 0.21982325 | O22: =AVERAGE($F$22:$L$22) -> 0.21982325 | P22: =AVERAGE($F$22:$L$22) -> 0.21982325 | Q22: =AVERAGE($F$22:$L$22) -> 0.21982325 | R22: =AVERAGE($F$22:$L$22) -> 0.21982325 | S22: =AVERAGE($F$22:$L$22) -> 0.21982325 | T22: =AVERAGE($F$22:$L$22) -> 0.21982325 | ... AB22: =AVERAGE($F$22:$L$22) -> 0.21982325
B23: Depreciation % Rev | C23: ='5. Re-org Fin Stmts'!C26/'2. Integrated Finance'!C9 -> 0.044038679 | D23: ='5. Re-org Fin Stmts'!D26/'2. Integrated Finance'!D9 -> 0.043324467 | E23: ='5. Re-org Fin Stmts'!E26/'2. Integrated Finance'!E9 -> 0.042609931 | F23: ='5. Re-org Fin Stmts'!F26/'2. Integrated Finance'!F9 -> 0.042901353 | G23: ='5. Re-org Fin Stmts'!G26/'2. Integrated Finance'!G9 -> 0.043174668 | H23: ='5. Re-org Fin Stmts'!H26/'2. Integrated Finance'!H9 -> 0.051347904 | I23: ='5. Re-org Fin Stmts'!I26/'2. Integrated Finance'!I9 -> 0.041922741 | J23: ='5. Re-org Fin Stmts'!J26/'2. Integrated Finance'!J9 -> 0.038920568 | ... L23: ='5. Re-org Fin Stmts'!L26/'2. Integrated Finance'!L9 -> 0.041248113 | M23: =AVERAGE($C23:$L23) -> 0.042676647 | N23: =AVERAGE($C23:$L23) -> 0.042676647 | O23: =AVERAGE($C23:$L23) -> 0.042676647 | P23: =AVERAGE($C23:$L23) -> 0.042676647 | Q23: =AVERAGE($C23:$L23) -> 0.042676647 | R23: =AVERAGE($C23:$L23) -> 0.042676647 | S23: =AVERAGE($C23:$L23) -> 0.042676647 | T23: =AVERAGE($C23:$L23) -> 0.042676647 | ... AB23: =AVERAGE($C23:$L23) -> 0.042676647
B25: BALANCE SHEET
B26: PARTICULARS | C26: ACTUALS | M26: NEAR TERM FORECAST | R26: FAR TERM FORECAST | AB26: CV
C27: =2015 -> 2015 | D27: =C27+1 -> 2016 | E27: =D27+1 -> 2017 | F27: =E27+1 -> 2018 | G27: =F27+1 -> 2019 | H27: =G27+1 -> 2020 | I27: =H27+1 -> 2021 | J27: =I27+1 -> 2022 | K27: =J27+1 -> 2023 | ... BV27: =BU27+1 -> 2086
C28: ="FY "&C27 -> FY 2015 | D28: ="FY "&D27 -> FY 2016 | E28: ="FY "&E27 -> FY 2017 | F28: ="FY "&F27 -> FY 2018 | G28: ="FY "&G27 -> FY 2019 | H28: ="FY "&H27 -> FY 2020 | I28: ="FY "&I27 -> FY 2021 | J28: ="FY "&J27 -> FY 2022 | ... AA28: ="FY "&AA27 -> FY 2039 | AB28: Perpetuity
B29: Net Operating Working Capital % Rev | C29: ='2. Integrated Finance'!C59/'2. Integrated Finance'!C9 -> 0.016850444 | D29: ='2. Integrated Finance'!D59/'2. Integrated Finance'!D9 -> 0.010020689 | E29: ='2. Integrated Finance'!E59/'2. Integrated Finance'!E9 -> 0.047469938 | F29: ='2. Integrated Finance'!F59/'2. Integrated Finance'!F9 -> 0.27549101 | G29: ='2. Integrated Finance'!G59/'2. Integrated Finance'!G9 -> -0.019420113 | H29: ='2. Integrated Finance'!H59/'2. Integrated Finance'!H9 -> 0.019542478 | I29: ='2. Integrated Finance'!I59/'2. Integrated Finance'!I9 -> 0.055229417 | J29: ='2. Integrated Finance'!J59/'2. Integrated Finance'!J9 -> -0.06614202 | ... L29: ='2. Integrated Finance'!L59/'2. Integrated Finance'!L9 -> -0.061438183 | M29: =AVERAGE($C$29:$L$29) -> 0.022084574 | N29: =AVERAGE($C$29:$L$29) -> 0.022084574 | O29: =AVERAGE($C$29:$L$29) -> 0.022084574 | P29: =AVERAGE($C$29:$L$29) -> 0.022084574 | Q29: =AVERAGE($C$29:$L$29) -> 0.022084574 | R29: =AVERAGE($C$29:$L$29) -> 0.022084574 | S29: =AVERAGE($C$29:$L$29) -> 0.022084574 | T29: =AVERAGE($C$29:$L$29) -> 0.022084574 | ... AB29: =AVERAGE($C$29:$L$29) -> 0.022084574
B30: Net Operating Long-Term Assets % Rev | C30: ='2. Integrated Finance'!C63/'2. Integrated Finance'!C9 -> 0.18198897 | D30: ='2. Integrated Finance'!D63/'2. Integrated Finance'!D9 -> 0.18033956 | E30: ='2. Integrated Finance'!E63/'2. Integrated Finance'!E9 -> 0.1860114 | F30: ='2. Integrated Finance'!F63/'2. Integrated Finance'!F9 -> -0.092117559 | G30: ='2. Integrated Finance'!G63/'2. Integrated Finance'!G9 -> -0.063496375 | H30: ='2. Integrated Finance'!H63/'2. Integrated Finance'!H9 -> -0.033676333 | I30: ='2. Integrated Finance'!I63/'2. Integrated Finance'!I9 -> -0.011469137 | J30: ='2. Integrated Finance'!J63/'2. Integrated Finance'!J9 -> 0.005292974 | ... L30: ='2. Integrated Finance'!L63/'2. Integrated Finance'!L9 -> 0.07077305 | M30: =AVERAGE($C$30:$L$30) -> 0.045865083 | N30: =AVERAGE($C$30:$L$30) -> 0.045865083 | O30: =AVERAGE($C$30:$L$30) -> 0.045865083 | P30: =AVERAGE($C$30:$L$30) -> 0.045865083 | Q30: =AVERAGE($C$30:$L$30) -> 0.045865083 | R30: =AVERAGE($C$30:$L$30) -> 0.045865083 | S30: =AVERAGE($C$30:$L$30) -> 0.045865083 | T30: =AVERAGE($C$30:$L$30) -> 0.045865083 | ... AB30: =AVERAGE($C$30:$L$30) -> 0.045865083
B31: Goodwill & Intangibles % Rev | C31: ='2. Integrated Finance'!C65/'2. Integrated Finance'!C9 -> 0.10936872 | D31: ='2. Integrated Finance'!D65/'2. Integrated Finance'!D9 -> 0.10489353 | E31: ='2. Integrated Finance'!E65/'2. Integrated Finance'!E9 -> 0.088471778 | F31: ='2. Integrated Finance'!F65/'2. Integrated Finance'!F9 -> 0.18543255 | G31: ='2. Integrated Finance'!G65/'2. Integrated Finance'!G9 -> 0.16117788 | H31: ='2. Integrated Finance'!H65/'2. Integrated Finance'!H9 -> 0.17643082 | I31: ='2. Integrated Finance'!I65/'2. Integrated Finance'!I9 -> 0.13857938 | J31: ='2. Integrated Finance'!J65/'2. Integrated Finance'!J9 -> 0.10664707 | ... L31: ='2. Integrated Finance'!L65/'2. Integrated Finance'!L9 -> 0.094443308 | M31: =AVERAGE($C$31:$L$31) -> 0.12582524 | N31: =AVERAGE($C$31:$L$31) -> 0.12582524 | O31: =AVERAGE($C$31:$L$31) -> 0.12582524 | P31: =AVERAGE($C$31:$L$31) -> 0.12582524 | Q31: =AVERAGE($C$31:$L$31) -> 0.12582524 | R31: =AVERAGE($C$31:$L$31) -> 0.12582524 | S31: =AVERAGE($C$31:$L$31) -> 0.12582524 | T31: =AVERAGE($C$31:$L$31) -> 0.12582524 | ... AB31: =AVERAGE($C$31:$L$31) -> 0.12582524
B32: Other Long-Term Assets % YoY | C32: ='2. Integrated Finance'!C69/'2. Integrated Finance'!C9 -> 0.11800007 | D32: ='2. Integrated Finance'!D69/'2. Integrated Finance'!D9 -> 0.1313245 | E32: ='2. Integrated Finance'!E69/'2. Integrated Finance'!E9 -> 0.097472618 | F32: ='2. Integrated Finance'!F69/'2. Integrated Finance'!F9 -> 0.046493659 | G32: ='2. Integrated Finance'!G69/'2. Integrated Finance'!G9 -> 0.10794233 | H32: ='2. Integrated Finance'!H69/'2. Integrated Finance'!H9 -> 0.12940301 | I32: ='2. Integrated Finance'!I69/'2. Integrated Finance'!I9 -> 0.10335299 | J32: ='2. Integrated Finance'!J69/'2. Integrated Finance'!J9 -> 0.091292174 | ... L32: ='2. Integrated Finance'!L69/'2. Integrated Finance'!L9 -> 0.08634406 | M32: =AVERAGE($C$32:$L$32) -> 0.099511534 | N32: =AVERAGE($C$32:$L$32) -> 0.099511534 | O32: =AVERAGE($C$32:$L$32) -> 0.099511534 | P32: =AVERAGE($C$32:$L$32) -> 0.099511534 | Q32: =AVERAGE($C$32:$L$32) -> 0.099511534 | R32: =AVERAGE($C$32:$L$32) -> 0.099511534 | S32: =AVERAGE($C$32:$L$32) -> 0.099511534 | T32: =AVERAGE($C$32:$L$32) -> 0.099511534 | ... AB32: =AVERAGE($C$32:$L$32) -> 0.099511534
B34: Long Term Debt % YoY | D34: =('2. Integrated Finance'!D84-'2. Integrated Finance'!C84)/'2. Integrated Finance'!C84 -> 0.36408946 | E34: =('2. Integrated Finance'!E84-'2. Integrated Finance'!D84)/'2. Integrated Finance'!D84 -> 0.22809319 | F34: =('2. Integrated Finance'!F84-'2. Integrated Finance'!E84)/'2. Integrated Finance'!E84 -> 1.3114988 | G34: =('2. Integrated Finance'!G84-'2. Integrated Finance'!F84)/'2. Integrated Finance'!F84 -> 0.22846582 | H34: =('2. Integrated Finance'!H84-'2. Integrated Finance'!G84)/'2. Integrated Finance'!G84 -> 0.99886272 | I34: =('2. Integrated Finance'!I84-'2. Integrated Finance'!H84)/'2. Integrated Finance'!H84 -> -0.043294969 | J34: =('2. Integrated Finance'!J84-'2. Integrated Finance'!I84)/'2. Integrated Finance'!I84 -> -0.03370655 | K34: =('2. Integrated Finance'!K84-'2. Integrated Finance'!J84)/'2. Integrated Finance'!J84 -> 0.040576493 | L34: =('2. Integrated Finance'!L84-'2. Integrated Finance'!K84)/'2. Integrated Finance'!K84 -> 0.075385146 | M34: 0.04 | N34: 0.04 | O34: 0.03 | P34: 0.03 | Q34: 0.03 | R34: 0.03 | S34: 0.02 | T34: 0.02 | U34: 0.02 | V34: 0.02 | W34: 0.02 | X34: 0.02 | Y34: 0.02 | Z34: 0.02 | AA34: 0.02 | AB34: 0.02
B35: Dividend Payout % Net Income | C35: =-'2. Integrated Finance'!C78/'2. Integrated Finance'!C77 -> 0.36853558 | D35: =-'2. Integrated Finance'!D78/'2. Integrated Finance'!D77 -> 0.44227561 | E35: =-'2. Integrated Finance'!E78/'2. Integrated Finance'!E77 -> 0.52549659 | F35: =-'2. Integrated Finance'!F78/'2. Integrated Finance'!F77 -> 0.3896377 | G35: =-'2. Integrated Finance'!G78/'2. Integrated Finance'!G77 -> 0.50055568 | H35: =-'2. Integrated Finance'!H78/'2. Integrated Finance'!H77 -> 1.5475601 | I35: =-'2. Integrated Finance'!I78/'2. Integrated Finance'!I77 -> 0.64229753 | J35: =-'2. Integrated Finance'!J78/'2. Integrated Finance'!J77 -> 0.69889688 | ... L35: =-'2. Integrated Finance'!L78/'2. Integrated Finance'!L77 -> 0.69797123 | M35: =AVERAGE($C$35:$L$35) -> 0.64132026 | N35: =AVERAGE($C$35:$L$35) -> 0.64132026 | O35: =AVERAGE($C$35:$L$35) -> 0.64132026 | P35: =AVERAGE($C$35:$L$35) -> 0.64132026 | Q35: =AVERAGE($C$35:$L$35) -> 0.64132026 | R35: =AVERAGE($C$35:$L$35) -> 0.64132026 | S35: =AVERAGE($C$35:$L$35) -> 0.64132026 | T35: =AVERAGE($C$35:$L$35) -> 0.64132026 | ... AB35: =AVERAGE($C$35:$L$35) -> 0.64132026
B36: Issued Equity % YoY | D36: =('2. Integrated Finance'!D89-'2. Integrated Finance'!C89)/'2. Integrated Finance'!C89 -> 0 | E36: =('2. Integrated Finance'!E89-'2. Integrated Finance'!D89)/'2. Integrated Finance'!D89 -> -0.0023474178 | F36: =('2. Integrated Finance'!F89-'2. Integrated Finance'!E89)/'2. Integrated Finance'!E89 -> -0.0023529412 | G36: =('2. Integrated Finance'!G89-'2. Integrated Finance'!F89)/'2. Integrated Finance'!F89 -> -0.0023584906 | H36: =('2. Integrated Finance'!H89-'2. Integrated Finance'!G89)/'2. Integrated Finance'!G89 -> 7.8676123 | I36: =('2. Integrated Finance'!I89-'2. Integrated Finance'!H89)/'2. Integrated Finance'!H89 -> 1.2588643 | J36: =('2. Integrated Finance'!J89-'2. Integrated Finance'!I89)/'2. Integrated Finance'!I89 -> -0.75640269 | K36: =('2. Integrated Finance'!K89-'2. Integrated Finance'!J89)/'2. Integrated Finance'!J89 -> -0.81007752 | L36: =('2. Integrated Finance'!L89-'2. Integrated Finance'!K89)/'2. Integrated Finance'!K89 -> 7.2576531 | M36: -0.01 | N36: -0.02 | O36: 0 | P36: 0 | Q36: 0 | R36: 0 | S36: 0.01 | T36: 0.01 | U36: 0.01 | V36: 0.01 | W36: 0.01 | X36: 0.01 | Y36: 0.01 | Z36: 0.01 | AA36: 0.01 | AB36: 0.01 | AC36: We analysed the movement in equity between the years 2015-2024 and noticed that it was extremely volatile, indicating that Starbucks' equity base has fluctuated drastically because of massive share-buybacks and retained earnings swings. Therefore, for the purpose of our estimation, we have removed the anomalous years, and took the remaining normal years giving us an average of -0.18%. This is exactly flat to slightly negative equity growth, which makes sense for a company consistently repurchasing shares.
I38: \

Sheet 4. Market Data & WACC
B1: ***Source: Bloomberg
B2: WACC
B3: 2015 | C3: =B3+1 -> 2016 | D3: =C3+1 -> 2017 | E3: =D3+1 -> 2018 | F3: =E3+1 -> 2019 | G3: =F3+1 -> 2020 | H3: =G3+1 -> 2021 | I3: =H3+1 -> 2022 | J3: =I3+1 -> 2023 | K3: =J3+1 -> 2024
B4: 0.085 | C4: 0.083 | D4: 0.092 | E4: 0.084 | F4: 0.071 | G4: 0.073 | H4: 0.099 | I4: 0.082 | J4: 0.091 | K4: 0.089
B6: Average WACC
B7: =AVERAGE(B4:K4) -> 0.0849
B9: Cost of Equity
B10: =B3 -> 2015 | C10: =C3 -> 2016 | D10: =D3 -> 2017 | E10: =E3 -> 2018 | F10: =F3 -> 2019 | G10: =G3 -> 2020 | H10: =H3 -> 2021 | I10: =I3 -> 2022 | ... K10: =K3 -> 2024
B11: 0.087 | C11: 0.086 | D11: 0.096 | E11: 0.09 | F11: 0.077 | G11: 0.09 | H11: 0.114 | I11: 0.092 | J11: 0.101 | K11: 0.101
B13: Average COE
B14: =AVERAGE(B11:K11) -> 0.0934

Sheet 5. Re-org Fin Stmts
B2: Re-organizing Financial Statements - Starbucks US
B5: INCOME STATEMENT
B6: PARTICULARS | C6: ACTUALS | M6: NEAR TERM FORECAST | R6: FAR TERM FORECAST | AB6: CV
C7: =2015 -> 2015 | D7: =C7+1 -> 2016 | E7: =D7+1 -> 2017 | F7: =E7+1 -> 2018 | G7: =F7+1 -> 2019 | H7: =G7+1 -> 2020 | I7: =H7+1 -> 2021 | J7: =I7+1 -> 2022 | K7: =J7+1 -> 2023 | ... BV7: =BU7+1 -> 2086
C8: ="FY "&C7 -> FY 2015 | D8: ="FY "&D7 -> FY 2016 | E8: ="FY "&E7 -> FY 2017 | F8: ="FY "&F7 -> FY 2018 | G8: ="FY "&G7 -> FY 2019 | H8: ="FY "&H7 -> FY 2020 | I8: ="FY "&I7 -> FY 2021 | J8: ="FY "&J7 -> FY 2022 | ... AA8: ="FY "&AA7 -> FY 2039 | AB8: Perpetuity
B9: Operating Profit after Tax | C9: ='2. Integrated Finance'!C24-'2. Integrated Finance'!C39 -> 2511.9 | D9: ='2. Integrated Finance'!D24-'2. Integrated Finance'!D39 -> 2792.2 | E9: ='2. Integrated Finance'!E24-'2. Integrated Finance'!E39 -> 2918.6 | F9: ='2. Integrated Finance'!F24-'2. Integrated Finance'!F39 -> 3233 | G9: ='2. Integrated Finance'!G24-'2. Integrated Finance'!G39 -> 3698.9 | H9: ='2. Integrated Finance'!H24-'2. Integrated Finance'!H39 -> 1893.5 | I9: ='2. Integrated Finance'!I24-'2. Integrated Finance'!I39 -> 4061.3 | J9: ='2. Integrated Finance'!J24-'2. Integrated Finance'!J39 -> 3906.5 | ... AB9: ='2. Integrated Finance'!AB24-'2. Integrated Finance'!AB39 -> 19934.728
B10: Less: Interest Tax Shield | C10: ='2. Integrated Finance'!C47 -> 20.658686 | D10: ='2. Integrated Finance'!D47 -> 26.715955 | E10: ='2. Integrated Finance'!E47 -> 30.692646 | F10: ='2. Integrated Finance'!F47 -> 37.183149 | G10: ='2. Integrated Finance'!G47 -> 64.596212 | H10: ='2. Integrated Finance'!H47 -> 89.95955 | I10: ='2. Integrated Finance'!I47 -> 101.43379 | J10: ='2. Integrated Finance'!J47 -> 108.23286 | ... AB10: ='2. Integrated Finance'!AB47 -> 71.385403
B11: NOPLAT | C11: =C9-C10 -> 2491.2413 | D11: =D9-D10 -> 2765.484 | E11: =E9-E10 -> 2887.9074 | F11: =F9-F10 -> 3195.8169 | G11: =G9-G10 -> 3634.3038 | H11: =H9-H10 -> 1803.5405 | I11: =I9-I10 -> 3959.8662 | J11: =J9-J10 -> 3798.2671 | ... AB11: =AB9-AB10 -> 19863.342
B12: Interest Expense after Tax | C12: ='2. Integrated Finance'!C28-'2. Integrated Finance'!C47 -> 49.841314 | D12: ='2. Integrated Finance'!D28-'2. Integrated Finance'!D47 -> 54.584045 | E12: ='2. Integrated Finance'!E28-'2. Integrated Finance'!E47 -> 61.807354 | F12: ='2. Integrated Finance'!F28-'2. Integrated Finance'!F47 -> 133.11685 | G12: ='2. Integrated Finance'!G28-'2. Integrated Finance'!G47 -> 266.40379 | H12: ='2. Integrated Finance'!H28-'2. Integrated Finance'!H47 -> 347.04045 | I12: ='2. Integrated Finance'!I28-'2. Integrated Finance'!I47 -> 368.36621 | J12: ='2. Integrated Finance'!J28-'2. Integrated Finance'!J47 -> 374.66714 | ... AB12: ='2. Integrated Finance'!AB28-'2. Integrated Finance'!AB47 -> 253.3546
B14: BALANCE SHEET
B15: PARTICULARS | C15: ACTUALS | M15: NEAR TERM FORECAST | R15: FAR TERM FORECAST | AB15: CV
C16: =2015 -> 2015 | D16: =C16+1 -> 2016 | E16: =D16+1 -> 2017 | F16: =E16+1 -> 2018 | G16: =F16+1 -> 2019 | H16: =G16+1 -> 2020 | I16: =H16+1 -> 2021 | J16: =I16+1 -> 2022 | K16: =J16+1 -> 2023 | ... BV16: =BU16+1 -> 2086
C17: ="FY "&C16 -> FY 2015 | D17: ="FY "&D16 -> FY 2016 | E17: ="FY "&E16 -> FY 2017 | F17: ="FY "&F16 -> FY 2018 | G17: ="FY "&G16 -> FY 2019 | H17: ="FY "&H16 -> FY 2020 | I17: ="FY "&I16 -> FY 2021 | J17: ="FY "&J16 -> FY 2022 | ... AA17: ="FY "&AA16 -> FY 2039 | AB17: Perpetuity
B18: Opening Working Capital | D18: =C20 -> 322.9 | E18: =D20 -> 213.6 | F18: =E20 -> 1062.7 | G18: =F20 -> 6810 | H18: =G20 -> -514.8 | I18: =H20 -> 459.6 | J18: =I20 -> 1605 | K18: =J20 -> -2133.1 | ... AB18: =AA20 -> 2679.4318
B19: Change in Working Capital | D19: =D20-D18 -> -109.3 | E19: =E20-E18 -> 849.1 | F19: =F20-F18 -> 5747.3 | G19: =G20-G18 -> -7324.8 | H19: =H20-H18 -> 974.4 | I19: =I20-I18 -> 1145.4 | J19: =J20-J18 -> -3738.1 | K19: =K20-K18 -> 91.2 | ... AB19: =AB20-AB18 -> 231.89202
B20: Closing Working Capital | C20: ='2. Integrated Finance'!C59 -> 322.9 | D20: ='2. Integrated Finance'!D59 -> 213.6 | E20: ='2. Integrated Finance'!E59 -> 1062.7 | F20: ='2. Integrated Finance'!F59 -> 6810 | G20: ='2. Integrated Finance'!G59 -> -514.8 | H20: ='2. Integrated Finance'!H59 -> 459.6 | I20: ='2. Integrated Finance'!I59 -> 1605 | J20: ='2. Integrated Finance'!J59 -> -2133.1 | ... AB20: ='2. Integrated Finance'!AB59 -> 2911.3238
B22: Opening Net Long-term Assets | D22: =C24 -> 3487.4 | E22: =D24 -> 3844.1 | F22: =E24 -> 4164.2 | G22: =F24 -> -2277.1 | H22: =G24 -> -1683.2 | I22: =H24 -> -792 | J22: =I24 -> -333.3 | K22: =J24 -> 170.7 | ... AB22: =AA24 -> 5564.6243
B23: Change in Net Long-term Assets | D23: =D24-D22 -> 356.7 | E23: =E24-E22 -> 320.1 | F23: =F24-F22 -> -6441.3 | G23: =G24-G22 -> 593.9 | H23: =H24-H22 -> 891.2 | I23: =I24-I22 -> 458.7 | J23: =J24-J22 -> 504 | K23: =K24-K22 -> 1088.6 | ... AB23: =AB24-AB22 -> 481.59165
B24: Closing Net Long-term Assets | C24: ='2. Integrated Finance'!C63 -> 3487.4 | D24: ='2. Integrated Finance'!D63 -> 3844.1 | E24: ='2. Integrated Finance'!E63 -> 4164.2 | F24: ='2. Integrated Finance'!F63 -> -2277.1 | G24: ='2. Integrated Finance'!G63 -> -1683.2 | H24: ='2. Integrated Finance'!H63 -> -792 | I24: ='2. Integrated Finance'!I63 -> -333.3 | J24: ='2. Integrated Finance'!J63 -> 170.7 | ... AB24: ='2. Integrated Finance'!AB63 -> 6046.216
